2024-03-31 17:18:28.205 WARNING (SyncWorker_3) [homeassistant.loader] We found a custom integration nodered which has not been tested by Home Assistant. This component might cause stability problems, be sure to disable it if you experience issues with Home Assistant
2024-03-31 17:18:28.207 WARNING (SyncWorker_3) [homeassistant.loader] We found a custom integration hacs which has not been tested by Home Assistant. This component might cause stability problems, be sure to disable it if you experience issues with Home Assistant
2024-03-31 17:18:31.953 WARNING (Recorder) [homeassistant.components.recorder.util] The system could not validate that the sqlite3 database at //config/home-assistant_v2.db was shutdown cleanly
2024-03-31 17:18:32.002 WARNING (Recorder) [homeassistant.components.recorder.util] Ended unfinished session (id=41 from 2024-03-31 10:58:55.254737)
2024-03-31 17:18:42.867 WARNING (MainThread) [homeassistant.setup] Setup of bluetooth is taking over 10 seconds.
2024-03-31 17:18:56.007 ERROR (Thread-2) [pychromecast.discovery] Unhandled exception in worker thread
Traceback (most recent call last):
  File "/usr/local/lib/python3.12/site-packages/pychromecast/discovery.py", line 302, in run
    self._poll_hosts()
  File "/usr/local/lib/python3.12/site-packages/pychromecast/discovery.py", line 328, in _poll_hosts
    device_status = get_device_info(host, timeout=30, context=self._context)
                    ^^^^^^^^^^^^^^^^^^^^^^^^^^^^^^^^^^^^^^^^^^^^^^^^^^^^^^^^
  File "/usr/local/lib/python3.12/site-packages/pychromecast/dial.py", line 184, in get_device_info
    _, status = _get_status(
                ^^^^^^^^^^^^
  File "/usr/local/lib/python3.12/site-packages/pychromecast/dial.py", line 95, in _get_status
    with urllib.request.urlopen(req, timeout=timeout, context=context) as response:
         ^^^^^^^^^^^^^^^^^^^^^^^^^^^^^^^^^^^^^^^^^^^^^^^^^^^^^^^^^^^^^
  File "/usr/local/lib/python3.12/urllib/request.py", line 215, in urlopen
    return opener.open(url, data, timeout)
           ^^^^^^^^^^^^^^^^^^^^^^^^^^^^^^^
  File "/usr/local/lib/python3.12/urllib/request.py", line 515, in open
    response = self._open(req, data)
               ^^^^^^^^^^^^^^^^^^^^^
  File "/usr/local/lib/python3.12/urllib/request.py", line 532, in _open
    result = self._call_chain(self.handle_open, protocol, protocol +
             ^^^^^^^^^^^^^^^^^^^^^^^^^^^^^^^^^^^^^^^^^^^^^^^^^^^^^^^
  File "/usr/local/lib/python3.12/urllib/request.py", line 492, in _call_chain
    result = func(*args)
             ^^^^^^^^^^^
  File "/usr/local/lib/python3.12/urllib/request.py", line 1392, in https_open
    return self.do_open(http.client.HTTPSConnection, req,
           ^^^^^^^^^^^^^^^^^^^^^^^^^^^^^^^^^^^^^^^^^^^^^^
  File "/usr/local/lib/python3.12/urllib/request.py", line 1313, in do_open
    h = http_class(host, timeout=req.timeout, **http_conn_args)
        ^^^^^^^^^^^^^^^^^^^^^^^^^^^^^^^^^^^^^^^^^^^^^^^^^^^^^^^
  File "/usr/local/lib/python3.12/http/client.py", line 1451, in __init__
    super(HTTPSConnection, self).__init__(host, port, timeout,
  File "/usr/local/lib/python3.12/http/client.py", line 878, in __init__
    self._validate_host(self.host)
  File "/usr/local/lib/python3.12/http/client.py", line 1280, in _validate_host
    raise InvalidURL(f"URL can't contain control characters. {host!r} "
http.client.InvalidURL: URL can't contain control characters. 'Lex Fridman' (found at least ' ')
2024-03-31 17:18:56.025 ERROR (Thread-2) [root] Uncaught thread exception
Traceback (most recent call last):
  File "/usr/local/lib/python3.12/threading.py", line 1073, in _bootstrap_inner
    self.run()
  File "/usr/local/lib/python3.12/site-packages/pychromecast/discovery.py", line 302, in run
    self._poll_hosts()
  File "/usr/local/lib/python3.12/site-packages/pychromecast/discovery.py", line 328, in _poll_hosts
    device_status = get_device_info(host, timeout=30, context=self._context)
                    ^^^^^^^^^^^^^^^^^^^^^^^^^^^^^^^^^^^^^^^^^^^^^^^^^^^^^^^^
  File "/usr/local/lib/python3.12/site-packages/pychromecast/dial.py", line 184, in get_device_info
    _, status = _get_status(
                ^^^^^^^^^^^^
  File "/usr/local/lib/python3.12/site-packages/pychromecast/dial.py", line 95, in _get_status
    with urllib.request.urlopen(req, timeout=timeout, context=context) as response:
         ^^^^^^^^^^^^^^^^^^^^^^^^^^^^^^^^^^^^^^^^^^^^^^^^^^^^^^^^^^^^^
  File "/usr/local/lib/python3.12/urllib/request.py", line 215, in urlopen
    return opener.open(url, data, timeout)
           ^^^^^^^^^^^^^^^^^^^^^^^^^^^^^^^
  File "/usr/local/lib/python3.12/urllib/request.py", line 515, in open
    response = self._open(req, data)
               ^^^^^^^^^^^^^^^^^^^^^
  File "/usr/local/lib/python3.12/urllib/request.py", line 532, in _open
    result = self._call_chain(self.handle_open, protocol, protocol +
             ^^^^^^^^^^^^^^^^^^^^^^^^^^^^^^^^^^^^^^^^^^^^^^^^^^^^^^^
  File "/usr/local/lib/python3.12/urllib/request.py", line 492, in _call_chain
    result = func(*args)
             ^^^^^^^^^^^
  File "/usr/local/lib/python3.12/urllib/request.py", line 1392, in https_open
    return self.do_open(http.client.HTTPSConnection, req,
           ^^^^^^^^^^^^^^^^^^^^^^^^^^^^^^^^^^^^^^^^^^^^^^
  File "/usr/local/lib/python3.12/urllib/request.py", line 1313, in do_open
    h = http_class(host, timeout=req.timeout, **http_conn_args)
        ^^^^^^^^^^^^^^^^^^^^^^^^^^^^^^^^^^^^^^^^^^^^^^^^^^^^^^^
  File "/usr/local/lib/python3.12/http/client.py", line 1451, in __init__
    super(HTTPSConnection, self).__init__(host, port, timeout,
  File "/usr/local/lib/python3.12/http/client.py", line 878, in __init__
    self._validate_host(self.host)
  File "/usr/local/lib/python3.12/http/client.py", line 1280, in _validate_host
    raise InvalidURL(f"URL can't contain control characters. {host!r} "
http.client.InvalidURL: URL can't contain control characters. 'Lex Fridman' (found at least ' ')
2024-03-31 17:27:04.604 ERROR (MainThread) [async_upnp_client.ssdp] Received error: [Errno 101] Network unreachable, transport: <_SelectorDatagramTransport fd=30 read=polling write=<idle, bufsize=0>>, socket: <asyncio.TransportSocket fd=30, family=2, type=2, proto=0, laddr=('0.0.0.0', 45460)>
2024-03-31 17:27:04.608 ERROR (MainThread) [async_upnp_client.ssdp] Received error: [Errno 101] Network unreachable, transport: <_SelectorDatagramTransport fd=33 read=polling write=<idle, bufsize=0>>, socket: <asyncio.TransportSocket fd=33, family=10, type=2, proto=0, laddr=('::', 60075, 0, 0)>
2024-03-31 17:27:34.606 ERROR (MainThread) [async_upnp_client.ssdp] Received error: [Errno 101] Network unreachable, transport: <_SelectorDatagramTransport fd=30 read=polling write=<idle, bufsize=0>>, socket: <asyncio.TransportSocket fd=30, family=2, type=2, proto=0, laddr=('0.0.0.0', 45460)>
2024-03-31 17:27:55.657 ERROR (MainThread) [homeassistant.components.homeassistant_alerts] Error requesting homeassistant_alerts data: Cannot connect to host alerts.home-assistant.io:443 ssl:default [Try again]
2024-03-31 17:28:04.611 ERROR (MainThread) [async_upnp_client.ssdp] Received error: [Errno 101] Network unreachable, transport: <_SelectorDatagramTransport fd=30 read=polling write=<idle, bufsize=0>>, socket: <asyncio.TransportSocket fd=30, family=2, type=2, proto=0, laddr=('0.0.0.0', 45460)>
2024-03-31 17:28:34.613 ERROR (MainThread) [async_upnp_client.ssdp] Received error: [Errno 101] Network unreachable, transport: <_SelectorDatagramTransport fd=30 read=polling write=<idle, bufsize=0>>, socket: <asyncio.TransportSocket fd=30, family=2, type=2, proto=0, laddr=('0.0.0.0', 45460)>
2024-03-31 17:28:38.619 ERROR (MainThread) [async_upnp_client.ssdp] Received error: [Errno 101] Network unreachable, transport: <_SelectorDatagramTransport fd=20 read=polling write=<idle, bufsize=0>>, socket: <asyncio.TransportSocket fd=20, family=2, type=2, proto=0, laddr=('0.0.0.0', 42942)>
2024-03-31 17:29:04.616 ERROR (MainThread) [async_upnp_client.ssdp] Received error: [Errno 101] Network unreachable, transport: <_SelectorDatagramTransport fd=30 read=polling write=<idle, bufsize=0>>, socket: <asyncio.TransportSocket fd=30, family=2, type=2, proto=0, laddr=('0.0.0.0', 45460)>
2024-03-31 17:29:34.618 ERROR (MainThread) [async_upnp_client.ssdp] Received error: [Errno 101] Network unreachable, transport: <_SelectorDatagramTransport fd=30 read=polling write=<idle, bufsize=0>>, socket: <asyncio.TransportSocket fd=30, family=2, type=2, proto=0, laddr=('0.0.0.0', 45460)>
2024-03-31 17:30:04.620 ERROR (MainThread) [async_upnp_client.ssdp] Received error: [Errno 101] Network unreachable, transport: <_SelectorDatagramTransport fd=30 read=polling write=<idle, bufsize=0>>, socket: <asyncio.TransportSocket fd=30, family=2, type=2, proto=0, laddr=('0.0.0.0', 45460)>
2024-03-31 17:30:34.624 ERROR (MainThread) [async_upnp_client.ssdp] Received error: [Errno 101] Network unreachable, transport: <_SelectorDatagramTransport fd=30 read=polling write=<idle, bufsize=0>>, socket: <asyncio.TransportSocket fd=30, family=2, type=2, proto=0, laddr=('0.0.0.0', 45460)>
2024-03-31 17:31:04.626 ERROR (MainThread) [async_upnp_client.ssdp] Received error: [Errno 101] Network unreachable, transport: <_SelectorDatagramTransport fd=30 read=polling write=<idle, bufsize=0>>, socket: <asyncio.TransportSocket fd=30, family=2, type=2, proto=0, laddr=('0.0.0.0', 45460)>
2024-03-31 17:31:34.628 ERROR (MainThread) [async_upnp_client.ssdp] Received error: [Errno 101] Network unreachable, transport: <_SelectorDatagramTransport fd=30 read=polling write=<idle, bufsize=0>>, socket: <asyncio.TransportSocket fd=30, family=2, type=2, proto=0, laddr=('0.0.0.0', 45460)>
2024-03-31 17:32:04.630 ERROR (MainThread) [async_upnp_client.ssdp] Received error: [Errno 101] Network unreachable, transport: <_SelectorDatagramTransport fd=30 read=polling write=<idle, bufsize=0>>, socket: <asyncio.TransportSocket fd=30, family=2, type=2, proto=0, laddr=('0.0.0.0', 45460)>
2024-03-31 17:32:34.632 ERROR (MainThread) [async_upnp_client.ssdp] Received error: [Errno 101] Network unreachable, transport: <_SelectorDatagramTransport fd=30 read=polling write=<idle, bufsize=0>>, socket: <asyncio.TransportSocket fd=30, family=2, type=2, proto=0, laddr=('0.0.0.0', 45460)>
2024-03-31 17:33:04.634 ERROR (MainThread) [async_upnp_client.ssdp] Received error: [Errno 101] Network unreachable, transport: <_SelectorDatagramTransport fd=30 read=polling write=<idle, bufsize=0>>, socket: <asyncio.TransportSocket fd=30, family=2, type=2, proto=0, laddr=('0.0.0.0', 45460)>
2024-03-31 17:33:34.637 ERROR (MainThread) [async_upnp_client.ssdp] Received error: [Errno 101] Network unreachable, transport: <_SelectorDatagramTransport fd=30 read=polling write=<idle, bufsize=0>>, socket: <asyncio.TransportSocket fd=30, family=2, type=2, proto=0, laddr=('0.0.0.0', 45460)>
2024-03-31 17:34:04.640 ERROR (MainThread) [async_upnp_client.ssdp] Received error: [Errno 101] Network unreachable, transport: <_SelectorDatagramTransport fd=30 read=polling write=<idle, bufsize=0>>, socket: <asyncio.TransportSocket fd=30, family=2, type=2, proto=0, laddr=('0.0.0.0', 45460)>
2024-03-31 17:34:09.533 ERROR (MainThread) [homeassistant.components.analytics] Error sending analytics to https://analytics-api.home-assistant.io/v1: ClientConnectorError(ConnectionKey(host='analytics-api.home-assistant.io', port=443, is_ssl=True, ssl=True, proxy=None, proxy_auth=None, proxy_headers_hash=319997378113707205), gaierror(-3, 'Try again'))
2024-03-31 17:34:34.645 ERROR (MainThread) [async_upnp_client.ssdp] Received error: [Errno 101] Network unreachable, transport: <_SelectorDatagramTransport fd=30 read=polling write=<idle, bufsize=0>>, socket: <asyncio.TransportSocket fd=30, family=2, type=2, proto=0, laddr=('0.0.0.0', 45460)>
2024-03-31 17:35:04.648 ERROR (MainThread) [async_upnp_client.ssdp] Received error: [Errno 101] Network unreachable, transport: <_SelectorDatagramTransport fd=30 read=polling write=<idle, bufsize=0>>, socket: <asyncio.TransportSocket fd=30, family=2, type=2, proto=0, laddr=('0.0.0.0', 45460)>
2024-03-31 17:35:34.651 ERROR (MainThread) [async_upnp_client.ssdp] Received error: [Errno 101] Network unreachable, transport: <_SelectorDatagramTransport fd=30 read=polling write=<idle, bufsize=0>>, socket: <asyncio.TransportSocket fd=30, family=2, type=2, proto=0, laddr=('0.0.0.0', 45460)>
2024-03-31 17:36:04.655 ERROR (MainThread) [async_upnp_client.ssdp] Received error: [Errno 101] Network unreachable, transport: <_SelectorDatagramTransport fd=30 read=polling write=<idle, bufsize=0>>, socket: <asyncio.TransportSocket fd=30, family=2, type=2, proto=0, laddr=('0.0.0.0', 45460)>
2024-03-31 17:37:25.877 ERROR (MainThread) [homeassistant.components.upnp] Error fetching Wireless Router TL-WR741N data: Unable to communicate with IGD at: http://192.168.0.1:1900/igd.xml
2024-03-31 17:41:04.678 ERROR (MainThread) [async_upnp_client.ssdp] Received error: [Errno 101] Network unreachable, transport: <_SelectorDatagramTransport fd=30 read=polling write=<idle, bufsize=0>>, socket: <asyncio.TransportSocket fd=30, family=2, type=2, proto=0, laddr=('0.0.0.0', 45460)>
2024-03-31 17:41:34.680 ERROR (MainThread) [async_upnp_client.ssdp] Received error: [Errno 101] Network unreachable, transport: <_SelectorDatagramTransport fd=30 read=polling write=<idle, bufsize=0>>, socket: <asyncio.TransportSocket fd=30, family=2, type=2, proto=0, laddr=('0.0.0.0', 45460)>
2024-03-31 17:42:04.688 ERROR (MainThread) [async_upnp_client.ssdp] Received error: [Errno 101] Network unreachable, transport: <_SelectorDatagramTransport fd=30 read=polling write=<idle, bufsize=0>>, socket: <asyncio.TransportSocket fd=30, family=2, type=2, proto=0, laddr=('0.0.0.0', 45460)>
2024-03-31 17:42:34.689 ERROR (MainThread) [async_upnp_client.ssdp] Received error: [Errno 101] Network unreachable, transport: <_SelectorDatagramTransport fd=30 read=polling write=<idle, bufsize=0>>, socket: <asyncio.TransportSocket fd=30, family=2, type=2, proto=0, laddr=('0.0.0.0', 45460)>
2024-03-31 17:43:04.700 ERROR (MainThread) [async_upnp_client.ssdp] Received error: [Errno 101] Network unreachable, transport: <_SelectorDatagramTransport fd=30 read=polling write=<idle, bufsize=0>>, socket: <asyncio.TransportSocket fd=30, family=2, type=2, proto=0, laddr=('0.0.0.0', 45460)>
2024-03-31 17:43:34.702 ERROR (MainThread) [async_upnp_client.ssdp] Received error: [Errno 101] Network unreachable, transport: <_SelectorDatagramTransport fd=30 read=polling write=<idle, bufsize=0>>, socket: <asyncio.TransportSocket fd=30, family=2, type=2, proto=0, laddr=('0.0.0.0', 45460)>
2024-03-31 17:44:00.634 WARNING (MainThread) [zeroconf] Error with socket 14 (('10.0.0.6', 5353))): [Errno 101] Network unreachable
Traceback (most recent call last):
  File "/usr/local/lib/python3.12/asyncio/selector_events.py", line 1261, in sendto
    self._sock.sendto(data, addr)
OSError: [Errno 101] Network unreachable
2024-03-31 17:44:00.650 ERROR (MainThread) [async_upnp_client.ssdp] Received error: [Errno 101] Network unreachable, transport: <_SelectorDatagramTransport fd=30 read=polling write=<idle, bufsize=0>>, socket: <asyncio.TransportSocket fd=30, family=2, type=2, proto=0, laddr=('0.0.0.0', 45460)>
2024-03-31 17:44:00.650 ERROR (MainThread) [async_upnp_client.ssdp] Received error: [Errno 101] Network unreachable, transport: <_SelectorDatagramTransport fd=30 read=polling write=<idle, bufsize=0>>, socket: <asyncio.TransportSocket fd=30, family=2, type=2, proto=0, laddr=('0.0.0.0', 45460)>
2024-03-31 17:44:00.651 ERROR (MainThread) [async_upnp_client.ssdp] Received error: [Errno 101] Network unreachable, transport: <_SelectorDatagramTransport fd=30 read=polling write=<idle, bufsize=0>>, socket: <asyncio.TransportSocket fd=30, family=2, type=2, proto=0, laddr=('0.0.0.0', 45460)>
