2024-03-15 20:07:23.594 WARNING (SyncWorker_3) [homeassistant.loader] We found a custom integration nodered which has not been tested by Home Assistant. This component might cause stability problems, be sure to disable it if you experience issues with Home Assistant
2024-03-15 20:07:23.598 WARNING (SyncWorker_3) [homeassistant.loader] We found a custom integration hacs which has not been tested by Home Assistant. This component might cause stability problems, be sure to disable it if you experience issues with Home Assistant
2024-03-15 20:07:27.298 WARNING (Recorder) [homeassistant.components.recorder.util] The system could not validate that the sqlite3 database at //config/home-assistant_v2.db was shutdown cleanly
2024-03-15 20:07:27.342 WARNING (Recorder) [homeassistant.components.recorder.util] Ended unfinished session (id=15 from 2024-03-11 21:53:50.131082)
2024-03-15 20:07:34.022 ERROR (MainThread) [async_upnp_client.ssdp] Received error: [Errno 101] Network unreachable, transport: <_SelectorDatagramTransport fd=21 read=polling write=<idle, bufsize=0>>, socket: <asyncio.TransportSocket fd=21, family=2, type=2, proto=0, laddr=('0.0.0.0', 54078)>
2024-03-15 20:07:34.022 ERROR (MainThread) [async_upnp_client.ssdp] Received error: [Errno 101] Network unreachable, transport: <_SelectorDatagramTransport fd=22 read=polling write=<idle, bufsize=0>>, socket: <asyncio.TransportSocket fd=22, family=2, type=2, proto=0, laddr=('0.0.0.0', 33046)>
2024-03-15 20:07:38.225 WARNING (MainThread) [homeassistant.setup] Setup of bluetooth is taking over 10 seconds.
2024-03-15 20:07:51.600 ERROR (Thread-2) [pychromecast.discovery] Unhandled exception in worker thread
Traceback (most recent call last):
  File "/usr/local/lib/python3.12/site-packages/pychromecast/discovery.py", line 302, in run
    self._poll_hosts()
  File "/usr/local/lib/python3.12/site-packages/pychromecast/discovery.py", line 328, in _poll_hosts
    device_status = get_device_info(host, timeout=30, context=self._context)
                    ^^^^^^^^^^^^^^^^^^^^^^^^^^^^^^^^^^^^^^^^^^^^^^^^^^^^^^^^
  File "/usr/local/lib/python3.12/site-packages/pychromecast/dial.py", line 184, in get_device_info
    _, status = _get_status(
                ^^^^^^^^^^^^
  File "/usr/local/lib/python3.12/site-packages/pychromecast/dial.py", line 95, in _get_status
    with urllib.request.urlopen(req, timeout=timeout, context=context) as response:
         ^^^^^^^^^^^^^^^^^^^^^^^^^^^^^^^^^^^^^^^^^^^^^^^^^^^^^^^^^^^^^
  File "/usr/local/lib/python3.12/urllib/request.py", line 215, in urlopen
    return opener.open(url, data, timeout)
           ^^^^^^^^^^^^^^^^^^^^^^^^^^^^^^^
  File "/usr/local/lib/python3.12/urllib/request.py", line 515, in open
    response = self._open(req, data)
               ^^^^^^^^^^^^^^^^^^^^^
  File "/usr/local/lib/python3.12/urllib/request.py", line 532, in _open
    result = self._call_chain(self.handle_open, protocol, protocol +
             ^^^^^^^^^^^^^^^^^^^^^^^^^^^^^^^^^^^^^^^^^^^^^^^^^^^^^^^
  File "/usr/local/lib/python3.12/urllib/request.py", line 492, in _call_chain
    result = func(*args)
             ^^^^^^^^^^^
  File "/usr/local/lib/python3.12/urllib/request.py", line 1392, in https_open
    return self.do_open(http.client.HTTPSConnection, req,
           ^^^^^^^^^^^^^^^^^^^^^^^^^^^^^^^^^^^^^^^^^^^^^^
  File "/usr/local/lib/python3.12/urllib/request.py", line 1313, in do_open
    h = http_class(host, timeout=req.timeout, **http_conn_args)
        ^^^^^^^^^^^^^^^^^^^^^^^^^^^^^^^^^^^^^^^^^^^^^^^^^^^^^^^
  File "/usr/local/lib/python3.12/http/client.py", line 1451, in __init__
    super(HTTPSConnection, self).__init__(host, port, timeout,
  File "/usr/local/lib/python3.12/http/client.py", line 878, in __init__
    self._validate_host(self.host)
  File "/usr/local/lib/python3.12/http/client.py", line 1280, in _validate_host
    raise InvalidURL(f"URL can't contain control characters. {host!r} "
http.client.InvalidURL: URL can't contain control characters. 'Lex Fridman' (found at least ' ')
2024-03-15 20:07:51.623 ERROR (Thread-2) [root] Uncaught thread exception
Traceback (most recent call last):
  File "/usr/local/lib/python3.12/threading.py", line 1073, in _bootstrap_inner
    self.run()
  File "/usr/local/lib/python3.12/site-packages/pychromecast/discovery.py", line 302, in run
    self._poll_hosts()
  File "/usr/local/lib/python3.12/site-packages/pychromecast/discovery.py", line 328, in _poll_hosts
    device_status = get_device_info(host, timeout=30, context=self._context)
                    ^^^^^^^^^^^^^^^^^^^^^^^^^^^^^^^^^^^^^^^^^^^^^^^^^^^^^^^^
  File "/usr/local/lib/python3.12/site-packages/pychromecast/dial.py", line 184, in get_device_info
    _, status = _get_status(
                ^^^^^^^^^^^^
  File "/usr/local/lib/python3.12/site-packages/pychromecast/dial.py", line 95, in _get_status
    with urllib.request.urlopen(req, timeout=timeout, context=context) as response:
         ^^^^^^^^^^^^^^^^^^^^^^^^^^^^^^^^^^^^^^^^^^^^^^^^^^^^^^^^^^^^^
  File "/usr/local/lib/python3.12/urllib/request.py", line 215, in urlopen
    return opener.open(url, data, timeout)
           ^^^^^^^^^^^^^^^^^^^^^^^^^^^^^^^
  File "/usr/local/lib/python3.12/urllib/request.py", line 515, in open
    response = self._open(req, data)
               ^^^^^^^^^^^^^^^^^^^^^
  File "/usr/local/lib/python3.12/urllib/request.py", line 532, in _open
    result = self._call_chain(self.handle_open, protocol, protocol +
             ^^^^^^^^^^^^^^^^^^^^^^^^^^^^^^^^^^^^^^^^^^^^^^^^^^^^^^^
  File "/usr/local/lib/python3.12/urllib/request.py", line 492, in _call_chain
    result = func(*args)
             ^^^^^^^^^^^
  File "/usr/local/lib/python3.12/urllib/request.py", line 1392, in https_open
    return self.do_open(http.client.HTTPSConnection, req,
           ^^^^^^^^^^^^^^^^^^^^^^^^^^^^^^^^^^^^^^^^^^^^^^
  File "/usr/local/lib/python3.12/urllib/request.py", line 1313, in do_open
    h = http_class(host, timeout=req.timeout, **http_conn_args)
        ^^^^^^^^^^^^^^^^^^^^^^^^^^^^^^^^^^^^^^^^^^^^^^^^^^^^^^^
  File "/usr/local/lib/python3.12/http/client.py", line 1451, in __init__
    super(HTTPSConnection, self).__init__(host, port, timeout,
  File "/usr/local/lib/python3.12/http/client.py", line 878, in __init__
    self._validate_host(self.host)
  File "/usr/local/lib/python3.12/http/client.py", line 1280, in _validate_host
    raise InvalidURL(f"URL can't contain control characters. {host!r} "
http.client.InvalidURL: URL can't contain control characters. 'Lex Fridman' (found at least ' ')
2024-03-15 20:07:54.489 ERROR (MainThread) [metno] Access to https://aa015h6buqvih86i1.api.met.no/weatherapi/locationforecast/2.0/complete returned error 'ClientConnectorError'
2024-03-15 20:08:05.187 ERROR (MainThread) [homeassistant.components.homeassistant_alerts] Error requesting homeassistant_alerts data: Cannot connect to host alerts.home-assistant.io:443 ssl:default [Try again]
2024-03-15 20:08:05.257 ERROR (MainThread) [metno] Access to https://aa015h6buqvih86i1.api.met.no/weatherapi/locationforecast/2.0/complete returned error 'ClientConnectorError'
2024-03-15 20:08:10.285 ERROR (MainThread) [custom_components.hacs] Could not update theme - Error fetching data from HACS: Cannot connect to host data-v2.hacs.xyz:443 ssl:default [Try again]
2024-03-15 20:08:10.286 ERROR (MainThread) [custom_components.hacs] Could not update integration - Error fetching data from HACS: Cannot connect to host data-v2.hacs.xyz:443 ssl:default [Try again]
2024-03-15 20:08:10.287 ERROR (MainThread) [custom_components.hacs] Could not update plugin - Error fetching data from HACS: Cannot connect to host data-v2.hacs.xyz:443 ssl:default [Try again]
2024-03-15 20:08:10.288 ERROR (MainThread) [custom_components.hacs] Could not update template - Error fetching data from HACS: Cannot connect to host data-v2.hacs.xyz:443 ssl:default [Try again]
2024-03-15 20:08:20.729 ERROR (MainThread) [metno] Access to https://aa015h6buqvih86i1.api.met.no/weatherapi/locationforecast/2.0/complete returned error 'ClientConnectorError'
2024-03-15 20:08:45.954 ERROR (MainThread) [metno] Access to https://aa015h6buqvih86i1.api.met.no/weatherapi/locationforecast/2.0/complete returned error 'ClientConnectorError'
2024-03-15 20:09:31.396 ERROR (MainThread) [metno] Access to https://aa015h6buqvih86i1.api.met.no/weatherapi/locationforecast/2.0/complete returned error 'ClientConnectorError'
2024-03-15 20:10:56.738 ERROR (MainThread) [metno] Access to https://aa015h6buqvih86i1.api.met.no/weatherapi/locationforecast/2.0/complete returned error 'ClientConnectorError'
2024-03-15 20:12:21.869 ERROR (MainThread) [metno] Access to https://aa015h6buqvih86i1.api.met.no/weatherapi/locationforecast/2.0/complete returned error 'ClientConnectorError'
2024-03-15 20:13:47.072 ERROR (MainThread) [metno] Access to https://aa015h6buqvih86i1.api.met.no/weatherapi/locationforecast/2.0/complete returned error 'ClientConnectorError'
2024-03-15 20:15:12.397 ERROR (MainThread) [metno] Access to https://aa015h6buqvih86i1.api.met.no/weatherapi/locationforecast/2.0/complete returned error 'ClientConnectorError'
2024-03-15 20:16:37.673 ERROR (MainThread) [metno] Access to https://aa015h6buqvih86i1.api.met.no/weatherapi/locationforecast/2.0/complete returned error 'ClientConnectorError'
2024-03-15 20:17:34.025 ERROR (MainThread) [async_upnp_client.ssdp] Received error: [Errno 101] Network unreachable, transport: <_SelectorDatagramTransport fd=21 read=polling write=<idle, bufsize=0>>, socket: <asyncio.TransportSocket fd=21, family=2, type=2, proto=0, laddr=('0.0.0.0', 54078)>
2024-03-15 20:17:34.026 ERROR (MainThread) [async_upnp_client.ssdp] Received error: [Errno 101] Network unreachable, transport: <_SelectorDatagramTransport fd=22 read=polling write=<idle, bufsize=0>>, socket: <asyncio.TransportSocket fd=22, family=2, type=2, proto=0, laddr=('0.0.0.0', 33046)>
2024-03-15 20:18:03.013 ERROR (MainThread) [metno] Access to https://aa015h6buqvih86i1.api.met.no/weatherapi/locationforecast/2.0/complete returned error 'ClientConnectorError'
2024-03-15 20:19:28.141 ERROR (MainThread) [metno] Access to https://aa015h6buqvih86i1.api.met.no/weatherapi/locationforecast/2.0/complete returned error 'ClientConnectorError'
2024-03-15 20:20:53.249 ERROR (MainThread) [metno] Access to https://aa015h6buqvih86i1.api.met.no/weatherapi/locationforecast/2.0/complete returned error 'ClientConnectorError'
2024-03-15 20:22:18.450 ERROR (MainThread) [metno] Access to https://aa015h6buqvih86i1.api.met.no/weatherapi/locationforecast/2.0/complete returned error 'ClientConnectorError'
2024-03-15 20:23:05.230 ERROR (MainThread) [homeassistant.components.analytics] Error sending analytics to https://analytics-api.home-assistant.io/v1: ClientConnectorError(ConnectionKey(host='analytics-api.home-assistant.io', port=443, is_ssl=True, ssl=True, proxy=None, proxy_auth=None, proxy_headers_hash=-5332183178832585766), gaierror(-3, 'Try again'))
2024-03-15 20:23:43.963 ERROR (MainThread) [metno] Access to https://aa015h6buqvih86i1.api.met.no/weatherapi/locationforecast/2.0/complete returned error 'ClientConnectorError'
2024-03-15 20:25:09.397 ERROR (MainThread) [metno] Access to https://aa015h6buqvih86i1.api.met.no/weatherapi/locationforecast/2.0/complete returned error 'ClientConnectorError'
2024-03-15 20:26:34.869 ERROR (MainThread) [metno] Access to https://aa015h6buqvih86i1.api.met.no/weatherapi/locationforecast/2.0/complete returned error 'ClientConnectorError'
2024-03-15 20:27:34.025 ERROR (MainThread) [async_upnp_client.ssdp] Received error: [Errno 101] Network unreachable, transport: <_SelectorDatagramTransport fd=21 read=polling write=<idle, bufsize=0>>, socket: <asyncio.TransportSocket fd=21, family=2, type=2, proto=0, laddr=('0.0.0.0', 54078)>
2024-03-15 20:27:34.026 ERROR (MainThread) [async_upnp_client.ssdp] Received error: [Errno 101] Network unreachable, transport: <_SelectorDatagramTransport fd=22 read=polling write=<idle, bufsize=0>>, socket: <asyncio.TransportSocket fd=22, family=2, type=2, proto=0, laddr=('0.0.0.0', 33046)>
2024-03-15 20:28:00.205 ERROR (MainThread) [metno] Access to https://aa015h6buqvih86i1.api.met.no/weatherapi/locationforecast/2.0/complete returned error 'ClientConnectorError'
2024-03-15 20:29:25.494 ERROR (MainThread) [metno] Access to https://aa015h6buqvih86i1.api.met.no/weatherapi/locationforecast/2.0/complete returned error 'ClientConnectorError'
2024-03-15 20:30:50.865 ERROR (MainThread) [metno] Access to https://aa015h6buqvih86i1.api.met.no/weatherapi/locationforecast/2.0/complete returned error 'ClientConnectorError'
2024-03-15 20:32:16.169 ERROR (MainThread) [metno] Access to https://aa015h6buqvih86i1.api.met.no/weatherapi/locationforecast/2.0/complete returned error 'ClientConnectorError'
2024-03-15 20:33:41.542 ERROR (MainThread) [metno] Access to https://aa015h6buqvih86i1.api.met.no/weatherapi/locationforecast/2.0/complete returned error 'ClientConnectorError'
2024-03-15 20:35:06.886 ERROR (MainThread) [metno] Access to https://aa015h6buqvih86i1.api.met.no/weatherapi/locationforecast/2.0/complete returned error 'ClientConnectorError'
2024-03-15 20:36:32.033 ERROR (MainThread) [metno] Access to https://aa015h6buqvih86i1.api.met.no/weatherapi/locationforecast/2.0/complete returned error 'ClientConnectorError'
2024-03-15 20:37:34.026 ERROR (MainThread) [async_upnp_client.ssdp] Received error: [Errno 101] Network unreachable, transport: <_SelectorDatagramTransport fd=21 read=polling write=<idle, bufsize=0>>, socket: <asyncio.TransportSocket fd=21, family=2, type=2, proto=0, laddr=('0.0.0.0', 54078)>
2024-03-15 20:37:34.027 ERROR (MainThread) [async_upnp_client.ssdp] Received error: [Errno 101] Network unreachable, transport: <_SelectorDatagramTransport fd=22 read=polling write=<idle, bufsize=0>>, socket: <asyncio.TransportSocket fd=22, family=2, type=2, proto=0, laddr=('0.0.0.0', 33046)>
2024-03-15 20:37:57.437 ERROR (MainThread) [metno] Access to https://aa015h6buqvih86i1.api.met.no/weatherapi/locationforecast/2.0/complete returned error 'ClientConnectorError'
2024-03-15 20:39:22.882 ERROR (MainThread) [metno] Access to https://aa015h6buqvih86i1.api.met.no/weatherapi/locationforecast/2.0/complete returned error 'ClientConnectorError'
2024-03-15 20:40:48.390 ERROR (MainThread) [metno] Access to https://aa015h6buqvih86i1.api.met.no/weatherapi/locationforecast/2.0/complete returned error 'ClientConnectorError'
2024-03-15 20:42:13.734 ERROR (MainThread) [metno] Access to https://aa015h6buqvih86i1.api.met.no/weatherapi/locationforecast/2.0/complete returned error 'ClientConnectorError'
2024-03-15 20:43:38.811 ERROR (MainThread) [metno] Access to https://aa015h6buqvih86i1.api.met.no/weatherapi/locationforecast/2.0/complete returned error 'ClientConnectorError'
2024-03-15 20:45:03.909 ERROR (MainThread) [metno] Access to https://aa015h6buqvih86i1.api.met.no/weatherapi/locationforecast/2.0/complete returned error 'ClientConnectorError'
2024-03-15 20:46:29.337 ERROR (MainThread) [metno] Access to https://aa015h6buqvih86i1.api.met.no/weatherapi/locationforecast/2.0/complete returned error 'ClientConnectorError'
2024-03-15 20:47:34.029 ERROR (MainThread) [async_upnp_client.ssdp] Received error: [Errno 101] Network unreachable, transport: <_SelectorDatagramTransport fd=21 read=polling write=<idle, bufsize=0>>, socket: <asyncio.TransportSocket fd=21, family=2, type=2, proto=0, laddr=('0.0.0.0', 54078)>
2024-03-15 20:47:34.030 ERROR (MainThread) [async_upnp_client.ssdp] Received error: [Errno 101] Network unreachable, transport: <_SelectorDatagramTransport fd=22 read=polling write=<idle, bufsize=0>>, socket: <asyncio.TransportSocket fd=22, family=2, type=2, proto=0, laddr=('0.0.0.0', 33046)>
2024-03-15 20:47:54.798 ERROR (MainThread) [metno] Access to https://aa015h6buqvih86i1.api.met.no/weatherapi/locationforecast/2.0/complete returned error 'ClientConnectorError'
2024-03-15 20:49:20.141 ERROR (MainThread) [metno] Access to https://aa015h6buqvih86i1.api.met.no/weatherapi/locationforecast/2.0/complete returned error 'ClientConnectorError'
2024-03-15 20:50:45.538 ERROR (MainThread) [metno] Access to https://aa015h6buqvih86i1.api.met.no/weatherapi/locationforecast/2.0/complete returned error 'ClientConnectorError'
2024-03-15 20:52:10.734 ERROR (MainThread) [metno] Access to https://aa015h6buqvih86i1.api.met.no/weatherapi/locationforecast/2.0/complete returned error 'ClientConnectorError'
2024-03-15 20:53:36.186 ERROR (MainThread) [metno] Access to https://aa015h6buqvih86i1.api.met.no/weatherapi/locationforecast/2.0/complete returned error 'ClientConnectorError'
2024-03-15 20:55:01.618 ERROR (MainThread) [metno] Access to https://aa015h6buqvih86i1.api.met.no/weatherapi/locationforecast/2.0/complete returned error 'ClientConnectorError'
2024-03-15 20:56:26.930 ERROR (MainThread) [metno] Access to https://aa015h6buqvih86i1.api.met.no/weatherapi/locationforecast/2.0/complete returned error 'ClientConnectorError'
2024-03-15 20:57:34.031 ERROR (MainThread) [async_upnp_client.ssdp] Received error: [Errno 101] Network unreachable, transport: <_SelectorDatagramTransport fd=21 read=polling write=<idle, bufsize=0>>, socket: <asyncio.TransportSocket fd=21, family=2, type=2, proto=0, laddr=('0.0.0.0', 54078)>
2024-03-15 20:57:34.033 ERROR (MainThread) [async_upnp_client.ssdp] Received error: [Errno 101] Network unreachable, transport: <_SelectorDatagramTransport fd=22 read=polling write=<idle, bufsize=0>>, socket: <asyncio.TransportSocket fd=22, family=2, type=2, proto=0, laddr=('0.0.0.0', 33046)>
2024-03-15 20:57:52.009 ERROR (MainThread) [metno] Access to https://aa015h6buqvih86i1.api.met.no/weatherapi/locationforecast/2.0/complete returned error 'ClientConnectorError'
2024-03-15 20:59:17.382 ERROR (MainThread) [metno] Access to https://aa015h6buqvih86i1.api.met.no/weatherapi/locationforecast/2.0/complete returned error 'ClientConnectorError'
2024-03-15 21:00:42.765 ERROR (MainThread) [metno] Access to https://aa015h6buqvih86i1.api.met.no/weatherapi/locationforecast/2.0/complete returned error 'ClientConnectorError'
2024-03-15 21:02:07.926 ERROR (MainThread) [metno] Access to https://aa015h6buqvih86i1.api.met.no/weatherapi/locationforecast/2.0/complete returned error 'ClientConnectorError'
2024-03-15 21:03:33.417 ERROR (MainThread) [metno] Access to https://aa015h6buqvih86i1.api.met.no/weatherapi/locationforecast/2.0/complete returned error 'ClientConnectorError'
2024-03-15 21:04:58.712 ERROR (MainThread) [metno] Access to https://aa015h6buqvih86i1.api.met.no/weatherapi/locationforecast/2.0/complete returned error 'ClientConnectorError'
2024-03-15 21:06:24.153 ERROR (MainThread) [metno] Access to https://aa015h6buqvih86i1.api.met.no/weatherapi/locationforecast/2.0/complete returned error 'ClientConnectorError'
2024-03-15 21:07:34.033 ERROR (MainThread) [async_upnp_client.ssdp] Received error: [Errno 101] Network unreachable, transport: <_SelectorDatagramTransport fd=21 read=polling write=<idle, bufsize=0>>, socket: <asyncio.TransportSocket fd=21, family=2, type=2, proto=0, laddr=('0.0.0.0', 54078)>
2024-03-15 21:07:34.034 ERROR (MainThread) [async_upnp_client.ssdp] Received error: [Errno 101] Network unreachable, transport: <_SelectorDatagramTransport fd=22 read=polling write=<idle, bufsize=0>>, socket: <asyncio.TransportSocket fd=22, family=2, type=2, proto=0, laddr=('0.0.0.0', 33046)>
2024-03-15 21:07:49.249 ERROR (MainThread) [metno] Access to https://aa015h6buqvih86i1.api.met.no/weatherapi/locationforecast/2.0/complete returned error 'ClientConnectorError'
2024-03-15 21:09:14.618 ERROR (MainThread) [metno] Access to https://aa015h6buqvih86i1.api.met.no/weatherapi/locationforecast/2.0/complete returned error 'ClientConnectorError'
2024-03-15 21:10:39.890 ERROR (MainThread) [metno] Access to https://aa015h6buqvih86i1.api.met.no/weatherapi/locationforecast/2.0/complete returned error 'ClientConnectorError'
2024-03-15 21:12:05.198 ERROR (MainThread) [metno] Access to https://aa015h6buqvih86i1.api.met.no/weatherapi/locationforecast/2.0/complete returned error 'ClientConnectorError'
2024-03-15 21:13:30.540 ERROR (MainThread) [metno] Access to https://aa015h6buqvih86i1.api.met.no/weatherapi/locationforecast/2.0/complete returned error 'ClientConnectorError'
2024-03-15 21:14:55.672 ERROR (MainThread) [metno] Access to https://aa015h6buqvih86i1.api.met.no/weatherapi/locationforecast/2.0/complete returned error 'ClientConnectorError'
2024-03-15 21:16:20.985 ERROR (MainThread) [metno] Access to https://aa015h6buqvih86i1.api.met.no/weatherapi/locationforecast/2.0/complete returned error 'ClientConnectorError'
2024-03-15 21:17:34.034 ERROR (MainThread) [async_upnp_client.ssdp] Received error: [Errno 101] Network unreachable, transport: <_SelectorDatagramTransport fd=21 read=polling write=<idle, bufsize=0>>, socket: <asyncio.TransportSocket fd=21, family=2, type=2, proto=0, laddr=('0.0.0.0', 54078)>
2024-03-15 21:17:34.037 ERROR (MainThread) [async_upnp_client.ssdp] Received error: [Errno 101] Network unreachable, transport: <_SelectorDatagramTransport fd=22 read=polling write=<idle, bufsize=0>>, socket: <asyncio.TransportSocket fd=22, family=2, type=2, proto=0, laddr=('0.0.0.0', 33046)>
2024-03-15 21:17:46.145 ERROR (MainThread) [metno] Access to https://aa015h6buqvih86i1.api.met.no/weatherapi/locationforecast/2.0/complete returned error 'ClientConnectorError'
2024-03-15 21:19:11.314 ERROR (MainThread) [metno] Access to https://aa015h6buqvih86i1.api.met.no/weatherapi/locationforecast/2.0/complete returned error 'ClientConnectorError'
2024-03-15 21:20:36.485 ERROR (MainThread) [metno] Access to https://aa015h6buqvih86i1.api.met.no/weatherapi/locationforecast/2.0/complete returned error 'ClientConnectorError'
2024-03-15 21:22:01.573 ERROR (MainThread) [metno] Access to https://aa015h6buqvih86i1.api.met.no/weatherapi/locationforecast/2.0/complete returned error 'ClientConnectorError'
2024-03-15 21:23:26.965 ERROR (MainThread) [metno] Access to https://aa015h6buqvih86i1.api.met.no/weatherapi/locationforecast/2.0/complete returned error 'ClientConnectorError'
2024-03-15 21:24:52.281 ERROR (MainThread) [metno] Access to https://aa015h6buqvih86i1.api.met.no/weatherapi/locationforecast/2.0/complete returned error 'ClientConnectorError'
2024-03-15 21:26:17.694 ERROR (MainThread) [metno] Access to https://aa015h6buqvih86i1.api.met.no/weatherapi/locationforecast/2.0/complete returned error 'ClientConnectorError'
2024-03-15 21:27:34.036 ERROR (MainThread) [async_upnp_client.ssdp] Received error: [Errno 101] Network unreachable, transport: <_SelectorDatagramTransport fd=21 read=polling write=<idle, bufsize=0>>, socket: <asyncio.TransportSocket fd=21, family=2, type=2, proto=0, laddr=('0.0.0.0', 54078)>
2024-03-15 21:27:34.037 ERROR (MainThread) [async_upnp_client.ssdp] Received error: [Errno 101] Network unreachable, transport: <_SelectorDatagramTransport fd=22 read=polling write=<idle, bufsize=0>>, socket: <asyncio.TransportSocket fd=22, family=2, type=2, proto=0, laddr=('0.0.0.0', 33046)>
2024-03-15 21:27:42.846 ERROR (MainThread) [metno] Access to https://aa015h6buqvih86i1.api.met.no/weatherapi/locationforecast/2.0/complete returned error 'ClientConnectorError'
2024-03-15 21:29:08.265 ERROR (MainThread) [metno] Access to https://aa015h6buqvih86i1.api.met.no/weatherapi/locationforecast/2.0/complete returned error 'ClientConnectorError'
2024-03-15 21:30:33.385 ERROR (MainThread) [metno] Access to https://aa015h6buqvih86i1.api.met.no/weatherapi/locationforecast/2.0/complete returned error 'ClientConnectorError'
2024-03-15 21:31:58.561 ERROR (MainThread) [metno] Access to https://aa015h6buqvih86i1.api.met.no/weatherapi/locationforecast/2.0/complete returned error 'ClientConnectorError'
2024-03-15 21:33:23.934 ERROR (MainThread) [metno] Access to https://aa015h6buqvih86i1.api.met.no/weatherapi/locationforecast/2.0/complete returned error 'ClientConnectorError'
2024-03-15 21:34:49.412 ERROR (MainThread) [metno] Access to https://aa015h6buqvih86i1.api.met.no/weatherapi/locationforecast/2.0/complete returned error 'ClientConnectorError'
2024-03-15 21:36:14.641 ERROR (MainThread) [metno] Access to https://aa015h6buqvih86i1.api.met.no/weatherapi/locationforecast/2.0/complete returned error 'ClientConnectorError'
2024-03-15 21:37:34.038 ERROR (MainThread) [async_upnp_client.ssdp] Received error: [Errno 101] Network unreachable, transport: <_SelectorDatagramTransport fd=21 read=polling write=<idle, bufsize=0>>, socket: <asyncio.TransportSocket fd=21, family=2, type=2, proto=0, laddr=('0.0.0.0', 54078)>
2024-03-15 21:37:34.039 ERROR (MainThread) [async_upnp_client.ssdp] Received error: [Errno 101] Network unreachable, transport: <_SelectorDatagramTransport fd=22 read=polling write=<idle, bufsize=0>>, socket: <asyncio.TransportSocket fd=22, family=2, type=2, proto=0, laddr=('0.0.0.0', 33046)>
2024-03-15 21:37:39.805 ERROR (MainThread) [metno] Access to https://aa015h6buqvih86i1.api.met.no/weatherapi/locationforecast/2.0/complete returned error 'ClientConnectorError'
2024-03-15 21:39:05.078 ERROR (MainThread) [metno] Access to https://aa015h6buqvih86i1.api.met.no/weatherapi/locationforecast/2.0/complete returned error 'ClientConnectorError'
2024-03-15 21:40:30.466 ERROR (MainThread) [metno] Access to https://aa015h6buqvih86i1.api.met.no/weatherapi/locationforecast/2.0/complete returned error 'ClientConnectorError'
2024-03-15 21:41:55.682 ERROR (MainThread) [metno] Access to https://aa015h6buqvih86i1.api.met.no/weatherapi/locationforecast/2.0/complete returned error 'ClientConnectorError'
2024-03-15 21:43:20.878 ERROR (MainThread) [metno] Access to https://aa015h6buqvih86i1.api.met.no/weatherapi/locationforecast/2.0/complete returned error 'ClientConnectorError'
2024-03-15 21:44:46.219 ERROR (MainThread) [metno] Access to https://aa015h6buqvih86i1.api.met.no/weatherapi/locationforecast/2.0/complete returned error 'ClientConnectorError'
2024-03-15 21:46:11.305 ERROR (MainThread) [metno] Access to https://aa015h6buqvih86i1.api.met.no/weatherapi/locationforecast/2.0/complete returned error 'ClientConnectorError'
2024-03-15 21:47:34.040 ERROR (MainThread) [async_upnp_client.ssdp] Received error: [Errno 101] Network unreachable, transport: <_SelectorDatagramTransport fd=21 read=polling write=<idle, bufsize=0>>, socket: <asyncio.TransportSocket fd=21, family=2, type=2, proto=0, laddr=('0.0.0.0', 54078)>
2024-03-15 21:47:34.041 ERROR (MainThread) [async_upnp_client.ssdp] Received error: [Errno 101] Network unreachable, transport: <_SelectorDatagramTransport fd=22 read=polling write=<idle, bufsize=0>>, socket: <asyncio.TransportSocket fd=22, family=2, type=2, proto=0, laddr=('0.0.0.0', 33046)>
2024-03-15 21:47:36.417 ERROR (MainThread) [metno] Access to https://aa015h6buqvih86i1.api.met.no/weatherapi/locationforecast/2.0/complete returned error 'ClientConnectorError'
2024-03-15 21:49:01.710 ERROR (MainThread) [metno] Access to https://aa015h6buqvih86i1.api.met.no/weatherapi/locationforecast/2.0/complete returned error 'ClientConnectorError'
2024-03-15 21:50:27.165 ERROR (MainThread) [metno] Access to https://aa015h6buqvih86i1.api.met.no/weatherapi/locationforecast/2.0/complete returned error 'ClientConnectorError'
2024-03-15 21:51:52.237 ERROR (MainThread) [metno] Access to https://aa015h6buqvih86i1.api.met.no/weatherapi/locationforecast/2.0/complete returned error 'ClientConnectorError'
2024-03-15 21:53:17.561 ERROR (MainThread) [metno] Access to https://aa015h6buqvih86i1.api.met.no/weatherapi/locationforecast/2.0/complete returned error 'ClientConnectorError'
2024-03-15 21:54:42.728 ERROR (MainThread) [metno] Access to https://aa015h6buqvih86i1.api.met.no/weatherapi/locationforecast/2.0/complete returned error 'ClientConnectorError'
2024-03-15 21:56:08.222 ERROR (MainThread) [metno] Access to https://aa015h6buqvih86i1.api.met.no/weatherapi/locationforecast/2.0/complete returned error 'ClientConnectorError'
2024-03-15 21:57:33.589 ERROR (MainThread) [metno] Access to https://aa015h6buqvih86i1.api.met.no/weatherapi/locationforecast/2.0/complete returned error 'ClientConnectorError'
2024-03-15 21:57:34.041 ERROR (MainThread) [async_upnp_client.ssdp] Received error: [Errno 101] Network unreachable, transport: <_SelectorDatagramTransport fd=21 read=polling write=<idle, bufsize=0>>, socket: <asyncio.TransportSocket fd=21, family=2, type=2, proto=0, laddr=('0.0.0.0', 54078)>
2024-03-15 21:57:34.042 ERROR (MainThread) [async_upnp_client.ssdp] Received error: [Errno 101] Network unreachable, transport: <_SelectorDatagramTransport fd=22 read=polling write=<idle, bufsize=0>>, socket: <asyncio.TransportSocket fd=22, family=2, type=2, proto=0, laddr=('0.0.0.0', 33046)>
2024-03-15 21:58:58.722 ERROR (MainThread) [metno] Access to https://aa015h6buqvih86i1.api.met.no/weatherapi/locationforecast/2.0/complete returned error 'ClientConnectorError'
2024-03-15 22:00:23.974 ERROR (MainThread) [metno] Access to https://aa015h6buqvih86i1.api.met.no/weatherapi/locationforecast/2.0/complete returned error 'ClientConnectorError'
2024-03-15 22:01:49.241 ERROR (MainThread) [metno] Access to https://aa015h6buqvih86i1.api.met.no/weatherapi/locationforecast/2.0/complete returned error 'ClientConnectorError'
2024-03-15 22:03:14.378 ERROR (MainThread) [metno] Access to https://aa015h6buqvih86i1.api.met.no/weatherapi/locationforecast/2.0/complete returned error 'ClientConnectorError'
2024-03-15 22:04:39.874 ERROR (MainThread) [metno] Access to https://aa015h6buqvih86i1.api.met.no/weatherapi/locationforecast/2.0/complete returned error 'ClientConnectorError'
2024-03-15 22:06:05.191 ERROR (MainThread) [metno] Access to https://aa015h6buqvih86i1.api.met.no/weatherapi/locationforecast/2.0/complete returned error 'ClientConnectorError'
2024-03-15 22:07:30.253 ERROR (MainThread) [metno] Access to https://aa015h6buqvih86i1.api.met.no/weatherapi/locationforecast/2.0/complete returned error 'ClientConnectorError'
2024-03-15 22:07:34.043 ERROR (MainThread) [async_upnp_client.ssdp] Received error: [Errno 101] Network unreachable, transport: <_SelectorDatagramTransport fd=21 read=polling write=<idle, bufsize=0>>, socket: <asyncio.TransportSocket fd=21, family=2, type=2, proto=0, laddr=('0.0.0.0', 54078)>
2024-03-15 22:07:34.045 ERROR (MainThread) [async_upnp_client.ssdp] Received error: [Errno 101] Network unreachable, transport: <_SelectorDatagramTransport fd=22 read=polling write=<idle, bufsize=0>>, socket: <asyncio.TransportSocket fd=22, family=2, type=2, proto=0, laddr=('0.0.0.0', 33046)>
2024-03-15 22:08:55.601 ERROR (MainThread) [metno] Access to https://aa015h6buqvih86i1.api.met.no/weatherapi/locationforecast/2.0/complete returned error 'ClientConnectorError'
2024-03-15 22:10:20.665 ERROR (MainThread) [metno] Access to https://aa015h6buqvih86i1.api.met.no/weatherapi/locationforecast/2.0/complete returned error 'ClientConnectorError'
2024-03-15 22:11:45.738 ERROR (MainThread) [metno] Access to https://aa015h6buqvih86i1.api.met.no/weatherapi/locationforecast/2.0/complete returned error 'ClientConnectorError'
2024-03-15 22:13:06.998 ERROR (MainThread) [metno] Access to https://aa015h6buqvih86i1.api.met.no/weatherapi/locationforecast/2.0/complete returned error 'ClientConnectorError'
2024-03-15 22:14:32.323 ERROR (MainThread) [metno] Access to https://aa015h6buqvih86i1.api.met.no/weatherapi/locationforecast/2.0/complete returned error 'ClientConnectorError'
2024-03-15 22:15:57.786 ERROR (MainThread) [metno] Access to https://aa015h6buqvih86i1.api.met.no/weatherapi/locationforecast/2.0/complete returned error 'ClientConnectorError'
2024-03-15 22:17:23.156 ERROR (MainThread) [metno] Access to https://aa015h6buqvih86i1.api.met.no/weatherapi/locationforecast/2.0/complete returned error 'ClientConnectorError'
2024-03-15 22:18:48.303 ERROR (MainThread) [metno] Access to https://aa015h6buqvih86i1.api.met.no/weatherapi/locationforecast/2.0/complete returned error 'ClientConnectorError'
2024-03-15 22:20:13.407 ERROR (MainThread) [metno] Access to https://aa015h6buqvih86i1.api.met.no/weatherapi/locationforecast/2.0/complete returned error 'ClientConnectorError'
